<?xml version="1.0"?>
<robot xmlns:xacro="http://www.ros.org/wiki/xacro" name="dog_robot_leg">

  <xacro:macro name="leg" params="prefix x_offset y_offset y_sign">

    <link name="${prefix}_hip_link">
      <visual>
        <origin xyz="0 0 0" rpy="0 0 0"/>
        <geometry>
          <mesh filename="package://dog_robot_description/meshes/visual/${prefix}_hip_link.stl"/>
        </geometry>
        <material name="grey"/>
      </visual>
      <collision>
        <origin xyz="0 0 0" rpy="0 0 0"/>
        <geometry>
          <mesh filename="package://dog_robot_description/meshes/collision/${prefix}_hip_link.stl"/>
        </geometry>
      </collision>
      <xacro:inertial_box mass="0.15" x="0.04" y="0.04" z="0.04">
        <origin xyz="0 0 0" rpy="0 0 0"/>
      </xacro:inertial_box>
    </link>

    <joint name="${prefix}_hip_yaw" type="revolute">
      <parent link="base_link"/>
      <child link="${prefix}_hip_link"/>
      <origin xyz="${x_offset} ${y_offset} 0" rpy="0 0 0"/>
      <axis xyz="1 0 0"/>
      <limit lower="-0.785" upper="0.785" effort="2.0" velocity="5.0"/>
      <dynamics damping="0.01" friction="0.0"/>
    </joint>

    <link name="${prefix}_thigh_link">
      <visual>
        <origin xyz="0 0 0" rpy="0 0 0"/>
        <geometry>
          <mesh filename="package://dog_robot_description/meshes/visual/${prefix}_thigh_link.stl"/>
        </geometry>
        <material name="dark_grey"/>
      </visual>
      <collision>
        <origin xyz="0 0 0" rpy="0 0 0"/>
        <geometry>
          <mesh filename="package://dog_robot_description/meshes/collision/${prefix}_thigh_link.stl"/>
        </geometry>
      </collision>
      <xacro:inertial_box mass="0.10" x="0.03" y="0.03" z="0.10">
        <origin xyz="0 0 -0.05" rpy="0 0 0"/>
      </xacro:inertial_box>
    </link>

    <joint name="${prefix}_thigh_pitch" type="revolute">
      <parent link="${prefix}_hip_link"/>
      <child link="${prefix}_thigh_link"/>
      <origin xyz="0 ${y_sign * 0.04895} 0" rpy="0 0 0"/>
      <axis xyz="0 1 0"/>
      <limit lower="-1.571" upper="1.571" effort="2.0" velocity="5.0"/>
      <dynamics damping="0.01" friction="0.0"/>
    </joint>

    <link name="${prefix}_shank_link">
      <visual>
        <origin xyz="0 0 0" rpy="0 0 0"/>
        <geometry>
          <mesh filename="package://dog_robot_description/meshes/visual/${prefix}_shank_link.stl"/>
        </geometry>
        <material name="grey"/>
      </visual>
      <collision>
        <origin xyz="0 0 0" rpy="0 0 0"/>
        <geometry>
          <mesh filename="package://dog_robot_description/meshes/collision/${prefix}_shank_link.stl"/>
        </geometry>
      </collision>
      <xacro:inertial_box mass="0.08" x="0.02" y="0.02" z="0.115">
        <origin xyz="0 0 -0.0575" rpy="0 0 0"/>
      </xacro:inertial_box>
    </link>

    <joint name="${prefix}_knee_pitch" type="revolute">
      <parent link="${prefix}_thigh_link"/>
      <child link="${prefix}_shank_link"/>
      <origin xyz="0 0 -0.109202" rpy="0 0 0"/>
      <axis xyz="0 1 0"/>
      <limit lower="0.0" upper="2.617" effort="2.0" velocity="5.0"/>
      <dynamics damping="0.01" friction="0.0"/>
    </joint>

    <link name="${prefix}_foot_link">
      <visual>
        <origin xyz="0 0 0" rpy="0 0 0"/>
        <geometry>
          <mesh filename="package://dog_robot_description/meshes/visual/${prefix}_foot_link.stl"/>
        </geometry>
        <material name="dark_grey"/>
      </visual>
      <collision>
        <origin xyz="0 0 0" rpy="0 0 0"/>
        <geometry>
          <mesh filename="package://dog_robot_description/meshes/collision/${prefix}_foot_link.stl"/>
        </geometry>
      </collision>
      <xacro:inertial_sphere mass="0.02" radius="0.015">
        <origin xyz="0 0 0" rpy="0 0 0"/>
      </xacro:inertial_sphere>
    </link>

    <joint name="${prefix}_foot_fixed" type="fixed">
      <parent link="${prefix}_shank_link"/>
      <child link="${prefix}_foot_link"/>
      <origin xyz="0 0 -0.115" rpy="0 0 0"/>
    </joint>

  </xacro:macro>

</robot>
