<?xml version="1.0"?>
<robot xmlns:xacro="http://www.ros.org/wiki/xacro" name="dog_robot_leg">

  <xacro:macro name="leg" params="prefix
                                  base_to_hip_xyz base_to_hip_rpy
                                  hip_to_thigh_xyz hip_to_thigh_rpy
                                  thigh_to_knee_xyz thigh_to_knee_rpy
                                  knee_to_foot_xyz knee_to_foot_rpy
                                  foot_sphere_xyz:='0 0 0'">

    <link name="${prefix}_hip_link">
      <visual>
        <origin xyz="0 0 0" rpy="0 0 0"/>
        <geometry>
          <mesh filename="package://dog_robot_description/meshes/visual_dh/${prefix}_hip_link.stl"/>
        </geometry>
        <material name="grey"/>
      </visual>
      <collision>
        <origin xyz="0 0 0" rpy="0 0 0"/>
        <geometry><box size="0.03 0.03 0.03"/></geometry>
      </collision>
    </link>

    <joint name="${prefix}_hip_roll" type="revolute">
      <parent link="base_link"/>
      <child link="${prefix}_hip_link"/>
      <origin xyz="${base_to_hip_xyz}" rpy="${base_to_hip_rpy}"/>
      <axis xyz="0 0 1"/>
      <limit lower="-0.785" upper="0.785" effort="10.0" velocity="8.0"/>
      <dynamics damping="0.5" friction="0.0"/>
    </joint>

    <link name="${prefix}_thigh_link">
      <visual>
        <origin xyz="0 0 0" rpy="0 0 0"/>
        <geometry>
          <mesh filename="package://dog_robot_description/meshes/visual_dh/${prefix}_thigh_link.stl"/>
        </geometry>
        <material name="dark_grey"/>
      </visual>
      <collision>
        <origin xyz="0 0 0" rpy="0 0 0"/>
        <geometry><box size="0.02 0.02 0.08"/></geometry>
      </collision>
    </link>

    <joint name="${prefix}_thigh_pitch" type="revolute">
      <parent link="${prefix}_hip_link"/>
      <child link="${prefix}_thigh_link"/>
      <origin xyz="${hip_to_thigh_xyz}" rpy="${hip_to_thigh_rpy}"/>
      <axis xyz="0 0 1"/>
      <limit lower="-1.571" upper="1.571" effort="10.0" velocity="8.0"/>
      <dynamics damping="0.5" friction="0.0"/>
    </joint>

    <link name="${prefix}_shank_link">
      <visual>
        <origin xyz="0 0 0" rpy="0 0 0"/>
        <geometry>
          <mesh filename="package://dog_robot_description/meshes/visual_dh/${prefix}_shank_link.stl"/>
        </geometry>
        <material name="grey"/>
      </visual>
      <collision>
        <origin xyz="0 0 0" rpy="0 0 0"/>
        <geometry><box size="0.015 0.015 0.10"/></geometry>
      </collision>
    </link>

    <joint name="${prefix}_knee_pitch" type="revolute">
      <parent link="${prefix}_thigh_link"/>
      <child link="${prefix}_shank_link"/>
      <origin xyz="${thigh_to_knee_xyz}" rpy="${thigh_to_knee_rpy}"/>
      <axis xyz="0 0 1"/>
      <limit lower="-2.617" upper="0.5" effort="10.0" velocity="8.0"/>
      <dynamics damping="0.5" friction="0.0"/>
    </joint>

    <link name="${prefix}_foot_link">
      <visual>
        <origin xyz="0 0 0" rpy="0 0 0"/>
        <geometry>
          <mesh filename="package://dog_robot_description/meshes/visual_dh/${prefix}_foot_link.stl"/>
        </geometry>
        <material name="dark_grey"/>
      </visual>
      <collision>
        <origin xyz="${foot_sphere_xyz}" rpy="0 0 0"/>
        <geometry><sphere radius="0.018"/></geometry>
      </collision>
    </link>

    <joint name="${prefix}_foot_fixed" type="fixed">
      <parent link="${prefix}_shank_link"/>
      <child link="${prefix}_foot_link"/>
      <origin xyz="${knee_to_foot_xyz}" rpy="${knee_to_foot_rpy}"/>
    </joint>

  </xacro:macro>

</robot>
