<?xml version="1.0"?>
<robot xmlns:xacro="http://www.ros.org/wiki/xacro" name="dog_robot_leg">

  <xacro:macro name="leg" params="prefix
                                  base_to_hip_xyz base_to_hip_rpy
                                  L_hh L_th L_sh
                                  mesh_hip_xyz mesh_hip_rpy
                                  mesh_thigh_xyz mesh_thigh_rpy
                                  mesh_shank_xyz mesh_shank_rpy
                                  mesh_foot_xyz mesh_foot_rpy
                                  foot_sphere_xyz:='0 0 0'">

    <link name="${prefix}_hip_link">
      <visual>
        <origin xyz="${mesh_hip_xyz}" rpy="${mesh_hip_rpy}"/>
        <geometry>
          <mesh filename="package://dog_robot_description/meshes/visual/${prefix}_hip_link.stl"/>
        </geometry>
        <material name="grey"/>
      </visual>
      <collision>
        <origin xyz="0 0 0" rpy="0 0 0"/>
        <geometry><box size="0.03 0.03 0.03"/></geometry>
      </collision>
      <xacro:inertial_box mass="0.15" x="0.04" y="0.04" z="0.04">
        <origin xyz="0 0 0" rpy="0 0 0"/>
      </xacro:inertial_box>
    </link>

    <joint name="${prefix}_hip_yaw" type="revolute">
      <parent link="base_link"/>
      <child link="${prefix}_hip_link"/>
      <origin xyz="${base_to_hip_xyz}" rpy="${base_to_hip_rpy}"/>
      <axis xyz="0 0 1"/>
      <limit lower="-0.785" upper="0.785" effort="5.0" velocity="8.0"/>
      <dynamics damping="0.05" friction="0.0"/>
    </joint>

    <link name="${prefix}_thigh_link">
      <visual>
        <origin xyz="${mesh_thigh_xyz}" rpy="${mesh_thigh_rpy}"/>
        <geometry>
          <mesh filename="package://dog_robot_description/meshes/visual/${prefix}_thigh_link.stl"/>
        </geometry>
        <material name="dark_grey"/>
      </visual>
      <collision>
        <origin xyz="0 0 0" rpy="0 0 0"/>
        <geometry><box size="0.02 0.02 0.08"/></geometry>
      </collision>
      <xacro:inertial_box mass="0.10" x="0.03" y="0.03" z="0.10">
        <origin xyz="0 0 0" rpy="0 0 0"/>
      </xacro:inertial_box>
    </link>

    <joint name="${prefix}_thigh_pitch" type="revolute">
      <parent link="${prefix}_hip_link"/>
      <child link="${prefix}_thigh_link"/>
      <origin xyz="${L_hh} 0 0" rpy="-1.5707963 0 0"/>
      <axis xyz="0 0 1"/>
      <limit lower="-1.571" upper="1.571" effort="5.0" velocity="8.0"/>
      <dynamics damping="0.05" friction="0.0"/>
    </joint>

    <link name="${prefix}_shank_link">
      <visual>
        <origin xyz="${mesh_shank_xyz}" rpy="${mesh_shank_rpy}"/>
        <geometry>
          <mesh filename="package://dog_robot_description/meshes/visual/${prefix}_shank_link.stl"/>
        </geometry>
        <material name="grey"/>
      </visual>
      <collision>
        <origin xyz="0 0 0" rpy="0 0 0"/>
        <geometry><box size="0.015 0.015 0.10"/></geometry>
      </collision>
      <xacro:inertial_box mass="0.08" x="0.02" y="0.02" z="0.115">
        <origin xyz="0 0 0" rpy="0 0 0"/>
      </xacro:inertial_box>
    </link>

    <joint name="${prefix}_knee_pitch" type="revolute">
      <parent link="${prefix}_thigh_link"/>
      <child link="${prefix}_shank_link"/>
      <origin xyz="${L_th} 0 0" rpy="0 0 0"/>
      <axis xyz="0 0 1"/>
      <limit lower="0.0" upper="2.617" effort="5.0" velocity="8.0"/>
      <dynamics damping="0.05" friction="0.0"/>
    </joint>

    <link name="${prefix}_foot_link">
      <visual>
        <origin xyz="${mesh_foot_xyz}" rpy="${mesh_foot_rpy}"/>
        <geometry>
          <mesh filename="package://dog_robot_description/meshes/visual/${prefix}_foot_link.stl"/>
        </geometry>
        <material name="dark_grey"/>
      </visual>
      <collision>
        <origin xyz="${foot_sphere_xyz}" rpy="0 0 0"/>
        <geometry><sphere radius="0.018"/></geometry>
      </collision>
      <xacro:inertial_sphere mass="0.02" radius="0.015">
        <origin xyz="0 0 0" rpy="0 0 0"/>
      </xacro:inertial_sphere>
    </link>

    <joint name="${prefix}_foot_fixed" type="fixed">
      <parent link="${prefix}_shank_link"/>
      <child link="${prefix}_foot_link"/>
      <origin xyz="${L_sh} 0 0" rpy="0 0 0"/>
    </joint>

  </xacro:macro>

</robot>
